Workbook
Name _rod2: [1]PLANNING!$B$44
Name C_: [1]PLANNING!$G$5
Name CAPEX: [1]Setup!$B$18:$C$18
Name D: [1]PLANNING!$G$2
Name data_bulkapproval: '[1]Completed Work'!#REF!
Name data_pump: '[1]Completed Work'!#REF!
Name data_SB: '[1]Completed Work'!#REF!
Name data_TB: '[1]Completed Work'!#REF!
Name data_wt_date_30: '[1]Completed Work'!#REF!
Name data_wt_date_60: '[1]Completed Work'!#REF!
Name data_wt_date_90: '[1]Completed Work'!#REF!
Name data_wt_date_ip: '[1]Completed Work'!#REF!
Name data_wt_date_prior: '[1]Completed Work'!#REF!
Name data_wt_gas_30: '[1]Completed Work'!#REF!
Name data_wt_gas_60: '[1]Completed Work'!#REF!
Name data_wt_gas_90: '[1]Completed Work'!#REF!
Name data_wt_gas_ip: '[1]Completed Work'!#REF!
Name data_wt_gas_prior: '[1]Completed Work'!#REF!
Name data_wt_oil_30: '[1]Completed Work'!#REF!
Name data_wt_oil_60: '[1]Completed Work'!#REF!
Name data_wt_oil_90: '[1]Completed Work'!#REF!
Name data_wt_oil_ip: '[1]Completed Work'!#REF!
Name data_wt_oil_prior: '[1]Completed Work'!#REF!
Name data_wt_water_30: '[1]Completed Work'!#REF!
Name data_wt_water_60: '[1]Completed Work'!#REF!
Name data_wt_water_90: '[1]Completed Work'!#REF!
Name data_wt_water_ip: '[1]Completed Work'!#REF!
Name data_wt_water_prior: '[1]Completed Work'!#REF!
Name ddd: [1]PLANNING!$G$40
Name DEV: [1]PLANNING!$B$4
Name KOP: [1]PLANNING!$B$11
Name L: [1]PLANNING!$G$4
Name list_action: [1]Setup!$D$33:$D$36
Name list_categories: [1]Setup!$A$33:$A$69
Name list_field: [1]Setup!$E$33:$E$45
Name list_name_lookup: [1]Setup!$G$34:$H$40
Name list_opexcapex: [1]Setup!$B$7:$B$9
Name list_priority: [1]Setup!$F$33:$F$38
Name list_pump: [1]Setup!#REF!
Name list_rig: [1]Setup!$A$7:$A$12
Name list_status: [1]Setup!$C$7:$C$15
Name list_welltype: [1]Setup!$D$7:$D$9
Name list_x: [1]Setup!$C$33:$C$33
Name list_yesno: [1]Setup!$J$18:$J$20
Name lll: [1]PLANNING!$G$42
Name OPEX: [1]Setup!$D$18:$G$18
Name OTHER: [1]Setup!$H$18
Name PHI: [1]PLANNING!$B$10
Name R_: [1]PLANNING!$G$1
Name ROB: [1]PLANNING!$B$5
Name rpt_end_date: '[1]Activity Report'!$L$6
Name rrr: [1]PLANNING!$G$39
Name sch_bulkapproval: [1]Schedule!#REF!
Name sch_pump: [1]Schedule!#REF!
Name sch_SB: [1]Schedule!#REF!
Name sch_TB: [1]Schedule!#REF!
Name sch_wt_date: [1]Schedule!#REF!
Name sch_wt_gas: [1]Schedule!#REF!
Name sch_wt_oil: [1]Schedule!#REF!
Name sch_wt_water: [1]Schedule!#REF!

Sheet Sketch
A1: Waddell TR 3 #3813 | B1: Waddell TR 3 #3813 | S1: Savanna #417
B2: ="Drilling Prognosis for "&S1 -> Drilling Prognosis for Savanna #417
S3: SHL Inputs | U3: BHL | X3: NOTES:
D4: Surface: | E4: =CONCATENATE(S4,"' ","F",T4,"L",", ",S5,"' ","F",T5,"L") -> 2010' FSL, 650' FWL | O4: AFE # | P4: CX3818 | S4: 2010 | T4: S | X4: Need to decide on motor
D5: Bottom: | E5: =E4 -> 2010' FSL, 650' FWL | O5: Well ID # | P5: 669 | S5: 650 | T5: W | X5: Do we need to take surface to GAU depth if we are setting intermediate?
E6: =CONCATENATE(T6," ",S6,", ",T7," ",S7) -> Sec 22, Blk B-25 | O6: Permit # | P6: 868552 | S6: 22 | T6: Sec | X6: Will need to move 13-3/8" BOP system off #415 to location
E7: PSL | O7: API # | P7: 42-103-36784 | S7: B-25 | T7: Blk | X7: Savanna to provide 4-1/2" DS-40 drill pipe
D8: LAT/LON (NAD83): | E8: 31.546657, -102.490691 | O8: Elevation | P8: =CONCATENATE("GL ",S8,"',"," KB ",(S8+12),"' (12' AGL)") -> GL 2765', KB 2777' (12' AGL) | S8: 2765 | T8: GL
D9: LAT/LON (NAD27): | E9: 31.546521, -102.490269 | O9: Lease: | P9: Waddell TR 3 | S9: 850 | T9: WTR
D10: County: | E10: Crane | O10: Field: | P10: University Waddell (Devonian)
D12: Geology | E12: Casing & Cement | J12: Wellhead | O12: General Notes
B14: TVD | D14: Formation | I14: GE API Head | O14: Notify RRC prior to spud
A15: =A16-150 -> -50 | J15: 17-1/2" | O15: & prior to running & cementing all casing strings
A16: =A17-150 -> 100
A17: =A18-150 -> 250 | B17: Near Surface | D17: Red Beds | O17: Drill out with 8.6 ppg FW, vis 33-36, pH > 9.0, no WL control
A18: =A19-150 -> 400 | E18: ="Lead: "&'Tech Data'!C48&" sx "&'Tech Data'!N48&"ppg Class C" -> Lead: 300 sx 12.8ppg Class C
A19: =A20-150 -> 550 | E19: ="Top of Lead @ "&'Tech Data'!U49&"'" -> Top of Lead @ 0' | O19: WL Totco Inc Survey every 500'
A20: =A21-150 -> 700 | E20: =" Lead Excess@ "&ROUND('Tech Data'!S48*100,-1) &"%" -> Lead Excess@ 30%
A21: =A22-150 -> 850
A22: =A23-150 -> 1000 | O22: Pump 2 sacks paper & 1/2 soap stick every 100' drilled
A23: =A24-150 -> 1150 | E23: ="Tail: " &'Tech Data'!C49&" sx "&'Tech Data'!N49&"ppg Class C" -> Tail: 250 sx 13.8ppg Class C | O23: Pump ~10 bbl high visc sweeps from slug pit every 100'-200'
A24: =A25-150 -> 1300 | E24: ="Top of Tail @ "&'Tech Data'!V49&"'" -> Top of Tail @ 600'
A25: =A26-150 -> 1450 | E25: =" Tail Excess@ "&ROUNDUP('Tech Data'!S49*100,-0.5) &"%" -> Tail Excess@ 86% | O25: Add 20sx of starch 300' from TD & circulate through steel pits as needed
A26: =A27-150 -> 1600 | O26: Pump the rest of the high visc pill when on bottom | S26: Thickness
A27: =A28-150 -> 1750 | D27: Rustler | S27: =D27 -> Rustler | U27: =B30-B27 -> 0
A28: 1900 | D28: Anhydrite | E28: 13-3/8" 48# H-40 STC | J28: 900 | O28: Test Casing to 1,000 psi
E29: =CONCATENATE("No deeper than ",S9+200,"' per TCEQ") -> No deeper than 1050' per TCEQ | J29: 11" | O29: RU H2S package
A30: =A31-180 -> 2020 | D30: Salado Salts | O30: RU mud loggers at start of Intermediate hole | S30: =D30 -> Salado Salts | U30: =B36-B30 -> 0
A31: =A32-180 -> 2200 | D31: Salts
A32: =A33-180 -> 2380 | E32: ="Lead: "&'Tech Data'!C50&" sx "&'Tech Data'!N50&"ppg Class C" -> Lead: 500 sx 11.6ppg Class C | O32: Drill out with 10.0 ppg Brine, vis 28-32, pH 10, no WL control
A33: =A34-180 -> 2560 | E33: ="Top of Lead @ "&'Tech Data'!U51&"'" -> Top of Lead @ 0' | O33: Refer to mud properties table
A34: =A35-180 -> 2740 | B34: ='Geo-Prog'!C28 -> 2278.7 | D34: ~ Yates | E34: =" Lead Excess@ "&ROUNDUP('Tech Data'!S50*100,-0.5) &"%" -> Lead Excess@ 84% | S34: =D36 -> 0 | U34: =B39-B36 -> 0
A35: =A36-180 -> 2920 | D35: Sands | O35: Survey every 200' in the Salts 650' - 2600'
A36: =A37-180 -> 3100 | E36: ="Tail: " &'Tech Data'!C51&" sx "&'Tech Data'!N51&"ppg Class H" -> Tail: 400 sx 14.4ppg Class H | S36: =D39 -> 0 | U36: =B42-B39 -> 3515.8
A37: =A38-180 -> 3280 | E37: ="Top of Tail @ "&'Tech Data'!V51&"'" -> Top of Tail @ 3000'
A38: =A39-180 -> 3460 | B38: ='Geo-Prog'!C29 -> 3056.3 | D38: ~Queen | E38: =" Tail Excess@ "&ROUNDUP('Tech Data'!S51*100,-0.5) &"%" -> Tail Excess@ 103% | S38: Queen | U38: =B46-B42 -> -3515.8
A39: =A40-180 -> 3640
A40: =A41-180 -> 3820
A41: =A42-180 -> 4000 | O41: Add 20sx of starch 300' from TD & circulate through steel pits as needed | S41: =D46 -> 0 | U41: =B49-B46 -> 5042.7
A42: =A43-180 -> 4180 | B42: ='Geo-Prog'!C30 -> 3515.8 | D42: ~ San Andres | O42: Pump the rest of the high visc pill when on bottom
...

Sheet Sketch_final
B1: =Sketch!B1 -> Waddell TR 3 #3813
B2: Drilling Recap
D4: Surface: | E4: =Sketch!E4 -> 2010' FSL, 650' FWL | O4: AFE # | P4: =Sketch!#REF! -> #REF!
D5: Bottom: | E5: =Sketch!E5 -> 2010' FSL, 650' FWL | O5: XTO ID # | P5: =Sketch!P7 -> 42-103-36784
E6: =Sketch!E6 -> Sec 22, Blk B-25 | O6: Permit # | P6: =Sketch!P4 -> CX3818
E7: =Sketch!E7 -> PSL | O7: API # | P7: =Sketch!#REF! -> #REF!
D8: County: | E8: =Sketch!E9 -> 31.546521, -102.490269 | O8: Elevation | P8: =Sketch!P8 -> GL 2765', KB 2777' (12' AGL)
D9: Field: | E9: =Sketch!E10 -> Crane | O9: Lease: | P9: =Sketch!P9 -> Waddell TR 3
D10: Well Plan: | E10: =Sketch!#REF! -> #REF!
D12: Geology | E12: Casing & Cement | J12: Wellhead | O12: General Notes | W12: TOC | X12: TOC | Y12: Est Circ | Z12: Est Circ | AA12: Col ht | AC12: Desired | AD12: Desired | AF12: Vol | AG12: Vol
S13: Vol | T13: Yield | U13: Est Losses | V13: Slurry | W13: w/loss | X13: no loss | Y13: w/loss | Z13: no loss | AA13: w/loss | AC13: Excess | AD13: TD | AE13: Yield | AF13: w/ex | AG13: no ex | AI13: Theoretical Ex | AK13: Circ vol | AL13: Act Loss
I14: GE API Head | R14: Surf Cement | S14: sx | T14: cuft/sx | U14: % | V14: bbl | W14: ft | X14: ft | Y14: sx | Z14: sx | AA14: ft | AC14: % | AD14: ft | AE14: cuft/sx | AF14: sx | AG14: sx | AI14: % | AK14: sx | AL14: %
B15: TVD | D15: Formation | J15: =Sketch!J15 -> 17-1/2" | O15: Conductor (not shown): | R15: Lead | S15: ='Tech Data'!C48 -> 300 | T15: ='Tech Data'!O48 -> 1.85 | U15: =AL15 -> 2.2520978 | V15: =S15*T15*0.1781 -> 98.8455 | W15: =IF(W16-V15/((W16*X22)*(1+U15))*W16<0,0,W16-V15/((W16*X22)*(1+U15))*W16) -> 0 | X15: =IF(W16-V15/((W16*X22)*(1))*W16<0,0,W16-V15/((W16*X22)*(1))*W16) -> 0 | Y15: =IF(W15=0,(V15-W16*X22*(1+U15))/0.1781/T15,0) -> 114 | Z15: =IF(X15=0,(V15-X16*X22)/0.1781/T15,0) -> 392.53721 | AA15: =U22-AA16 -> 416.19406 | AC15: 1.5 | AD15: 0 | AE15: =T15 -> 1.85 | AF15: =(AD16-AD15)*X22/0.1781/AE15*(1+AC15) -> 137.42111 | AG15: =(AD16-AD15)*X22/0.1781/AE15*(1) -> 54.968446 | AI15: =S15/AG15-1 -> 4.4576766 | AK15: 114 | AL15: =(V17-(AK15*T15*0.1781))/T25-1 -> 2.2520978
A16: 100 | O16: 16" hole to 53', 14" 40# Construction (B) csg, cmt w/13 sx to surf | R16: Tail | S16: ='Tech Data'!C49 -> 250 | T16: ='Tech Data'!O49 -> 1.6 | U16: =U15 -> 2.2520978 | V16: =S16*T16*0.1781 -> 71.24 | W16: =U22-V16/(T25*(1+U16))*U22 -> 416.19406 | X16: =U22-V16/(T25*(1))*U22 -> -673.38424 | AA16: =U22-W16 -> 483.80594 | AC16: 1.5 | AD16: =ROUND(W16,-2) -> 400 | AE16: =T16 -> 1.6 | AF16: =(U22-AD16)*X22/0.1781/AE16*(1+AC16) -> 198.61646 | AG16: =(U22-AD16)*X22/0.1781/AE16*(1) -> 79.446582 | AI16: =S16/AG16-1 -> 2.1467685
A17: 200 | B17: =IF(Sketch!B17="","",Sketch!B17) -> Near Surface | D17: Red Beds | E17: =Sketch!E18 -> Lead: 300 sx 12.8ppg Class C | R17: Total | S17: =SUM(S15:S16) -> 550 | V17: =SUM(V15:V16) -> 170.0855 | AF17: =SUM(AF15:AF16) -> 336.03757 | AG17: =SUM(AG15:AG16) -> 134.41503 | AI17: =S17/AG17-1 -> 3.0918044
A18: 300 | B18: =IF(Sketch!B18="","",Sketch!B18) | E18: =Sketch!#REF! -> #REF! | O18: Surface Wellhead:
A19: 1000 | B19: =IF(Sketch!B19="","",Sketch!B19) | E19: =Sketch!E19 -> Top of Lead @ 0' | O19: GE A Section casing head, 8-5/8" SOW x 11" 3M (test 1000 psig) | S19: ID | T19: OD | U19: Depth | V19: ID Cap | W19: OD Cap | X19: Ann Cap
A20: 1100 | B20: =IF(Sketch!B20="","",Sketch!B20) | E20: Circ 114 Sx, (calc 126% loss) | R20: Surface | S20: in | T20: in | U20: ft | V20: bbl/ft | W20: bbl/ft | X20: bbl/ft
A21: 1200 | B21: =IF(Sketch!B21="","",Sketch!B21) | O21: Surf Bit / BHA: | R21: Surf Hole | S21: 11 | U21: =J28 -> 900 | V21: =S21^2/1029.4 -> 0.1175442
A22: 1300 | B22: =IF(Sketch!B22="","",Sketch!B22) | E22: =Sketch!E22 -> 0 | O22: ='Tech Data'!D15&" "&'Tech Data'!E15&" "&'Tech Data'!B15&" bit ("&'Tech Data'!G15&" jets)" -> GT65DM PDC bit ( jets) | R22: Surf Csg in OH | S22: 8.097 | T22: 8.625 | U22: =U21 -> 900 | V22: =S22^2/1029.4 -> 0.063688954 | W22: =T22^2/1029.4 -> 0.072266004 | X22: =(V21-W22) -> 0.045278196
A23: 1400 | B23: =IF(Sketch!B23="","",Sketch!B23) | E23: =Sketch!E23 -> Tail: 250 sx 13.8ppg Class C | O23: ='Tech Data'!I15 -> Bit > Bit sub & float > 2 x 8"DC > XO > 10 x 6-1/2" DC > 10 x 4-1/2" HWDP
A24: 1500 | B24: =IF(Sketch!B24="","",Sketch!B24) | E24: 1160 | S24: Surface casing volume: | T24: =V22*U22 -> 57.320058 | U24: bbl
A25: 1600 | B25: =IF(Sketch!B25="","",Sketch!B25) | O25: Surface Hole Comments | S25: Surface annular volume: | T25: =X22*U21 -> 40.750376 | U25: bbl
A26: 1700 | B26: =IF(Sketch!B26="","",Sketch!B26) | O26: - Washed down last jt of casing - Floats held, tag @ 1885'
A27: 1800 | B27: =IF(Sketch!B27="","",Sketch!B27) | D27: =IF(Sketch!D27<>"",Sketch!D27,"") -> Rustler | W27: TOC | X27: TOC | Y27: Est Circ | Z27: Est Circ | AA27: Col ht | AC27: Desired | AD27: Desired | AF27: Vol | AG27: Vol
A28: 1900 | B28: =IF(Sketch!B28="","",Sketch!B28) | D28: =IF(Sketch!D28<>"",Sketch!D28,"") -> Anhydrite | E28: =Sketch!E28 -> 13-3/8" 48# H-40 STC | J28: =Sketch!J28 -> 900 | S28: Vol | T28: Yield | U28: Est Losses | V28: Slurry | W28: w/loss | X28: no loss | Y28: w/loss | Z28: no loss | AA28: w/loss | AC28: Excess | AD28: TD | AE28: Yield | AF28: w/ex | AG28: no ex | AI28: Theoretical Ex | AK28: Circ vol | AL28: Act Loss
A29: 2000 | B29: =IF(Sketch!B29="","",Sketch!B29) | D29: =IF(Sketch!D29<>"",Sketch!D29,"") | E29: =Sketch!E29 -> No deeper than 1050' per TCEQ | J29: =Sketch!J29 -> 11" | O29: Production Wellhead: | R29: Prod Cement | S29: sx | T29: cuft/sx | U29: % | V29: bbl | W29: ft | X29: ft | Y29: sx | Z29: sx | AA29: ft | AC29: % | AD29: ft | AE29: cuft/sx | AF29: sx | AG29: sx | AI29: % | AK29: sx | AL29: %
A30: 2100 | B30: =IF(Sketch!B30="","",Sketch!B30) | D30: =IF(Sketch!D30<>"",Sketch!D30,"") -> Salado Salts | O30: GE B Section tubing head, 11" 3M x 7-1/16" 5M (test 2400 psig) | R30: Lead | S30: ='Tech Data'!C52 -> 500 | T30: ='Tech Data'!O52 -> 2.82 | U30: =AL30 -> 0.29366572 | V30: =S30*T30*0.1781 -> 251.121 | W30: =IF(IF(W31<U38,W31-V30/(((W31*X37))*(1+U30))*W31,W31-V30/(((T42+(W31-U38)*X38))*(1+U30))*W31)<0,0,IF(W31<U38,W31-V30/(((W31*X37))*(1+U30))*W31,W31-V30/(((T42+(W31-U38)*X38))*(1+U30))*W31)) -> 0 | X30: =IF(IF(W31<U38,W31-V30/(((W31*X37))*(1))*W31,W31-V30/(((T42+(W31-U38)*X38))*(1))*W31)<0,0,IF(W31<U38,W31-V30/(((W31*X37))*(1))*W31,W31-V30/(((T42+(W31-U38)*X38))*(1))*W31)) -> 0 | Y30: =IF(W30=0,(V30-W31*X37*(1+U30))/0.1781/T30,0) -> 44.365303 | Z30: =IF(X30=0,(V30-X31*X37)/0.1781/T30,0) -> 244.93767 | AA30: =U38-AA31 -> 5156.7593 | AC30: 1.5 | AD30: 0 | AE30: =T30 -> 2.82 | AF30: =(AD31-AD30)*X37/0.1781/AE30*(1+AC30) -> 887.89418 | AG30: =(AD31-AD30)*X37/0.1781/AE30*(1) -> 355.15767 | AI30: =S30/AG30-1 -> 0.40782543 | AK30: 86 | AL30: =(V32-(AK30*T30*0.1781))/T43-1 -> 0.29366572
A31: 2200 | B31: =IF(Sketch!B31="","",Sketch!B31) | D31: =IF(Sketch!D31<>"",Sketch!D31,"") -> Salts | R31: Tail | S31: ='Tech Data'!C53 -> 850 | T31: ='Tech Data'!O53 -> 1.29 | U31: =U30 -> 0.29366572 | V31: =S31*T31*0.1781 -> 195.28665 | W31: =U38-V31/((T41+T42)*(1+U31))*U38 -> 5156.7593 | X31: =U38-V31/((T41+T42)*(1))*U38 -> 3734.4656 | AA31: =U38-W31 -> 4843.2407 | AC31: 1.5 | AD31: =ROUND(W31,-2) -> 5200 | AE31: =T31 -> 1.29 | AF31: =(U38-AD31)*X38/0.1781/AE31*(1+AC31) -> 1611.7618 | AG31: =(U38-AD31)*X38/0.1781/AE31*(1) -> 644.70472 | AI31: =S31/AG31-1 -> 0.31843304
A32: 3600 | B32: =IF(Sketch!B33="","",Sketch!B33) | D32: =IF(Sketch!D39<>"",Sketch!D39,"") | E32: =Sketch!E32 -> Lead: 500 sx 11.6ppg Class C | O32: Bit / BHA: | R32: Total | S32: =SUM(S30:S31) -> 1350 | V32: =SUM(V30:V31) -> 446.40765 | AF32: =SUM(AF30:AF31) -> 2499.656 | AG32: =SUM(AG30:AG31) -> 999.86239 | AI32: =S32/AG32-1 -> 0.3501858
B33: =IF(Sketch!B36="","",Sketch!B36) | D33: =IF(Sketch!D40<>"",Sketch!D40,"") | E33: =Sketch!E50 -> Lead: 500 sx 11.6ppg Class C | O33: ='Tech Data'!D17&" "&'Tech Data'!E17&" "&'Tech Data'!B17&" bit ("&'Tech Data'!G17&" jets)" -> GT65WRK PDC bit (1.035 jets)
A34: 3700 | B34: =IF(Sketch!B37="","",Sketch!B37) | D34: =IF(Sketch!D37<>"",Sketch!D37,"") | E34: =Sketch!E51 -> Top of Lead @ 0' | O34: ='Tech Data'!I17 -> Bit > Motor w/float > Monel w/ MWD survey tool > XO >6-1/2" STAB > 1 x 4-1/2" DC > 6-1/2" STAB > 31 x 4-1/2" HWDP > 4-1/2" 16.6# G-105 EU DP | S34: ID | T34: OD | U34: Depth | V34: ID Cap | W34: OD Cap | X34: Ann Cap
A35: 3800 | B35: =IF(Sketch!B39="","",Sketch!B39) | D35: =IF(Sketch!#REF!<>"",Sketch!#REF!,"") -> #REF! | E35: Circ 86 Sx, (calc 91% loss) | R35: Production | S35: in | T35: in | U35: ft | V35: bbl/ft | W35: bbl/ft | X35: bbl/ft
A36: 3900 | B36: =IF(Sketch!B40="","",Sketch!B40) | D36: =IF(Sketch!#REF!<>"",Sketch!#REF!,"") -> #REF! | E36: =IF(Sketch!E36<>"",Sketch!E36,"") -> Tail: 400 sx 14.4ppg Class H | R36: Prod Hole | S36: 7.875 | U36: =J61 -> 10000 | V36: =S36^2/1029.4 -> 0.060244439
A37: 4000 | B37: =IF(Sketch!#REF!="","",Sketch!#REF!) -> #REF! | D37: =IF(Sketch!#REF!<>"",Sketch!#REF!,"") -> #REF! | E37: =IF(Sketch!E37<>"",Sketch!E37,"") -> Top of Tail @ 3000' | O37: Max DLS: 0.28 deg / 100' @ 5087' MD | R37: Prod Csg in Surf | S37: =S38 -> 4.892 | T37: =T38 -> 5.5 | U37: =U22 -> 900 | V37: =V38 -> 0.023248168 | W37: =W38 -> 0.02938605 | X37: =(V22-W37) -> 0.034302904 | AC37: fix Est Circ & Vol w/ex
A38: 4100 | B38: =IF(Sketch!#REF!="","",Sketch!#REF!) -> #REF! | D38: =IF(Sketch!D46<>"",Sketch!D46,"") | E38: =IF(Sketch!E38<>"",Sketch!E38,"") -> Tail Excess@ 103% | O38: Max inc: 2 deg @ 1241' | R38: Prod Csg in OH | S38: 4.892 | T38: 5.5 | U38: =U36 -> 10000 | V38: =S38^2/1029.4 -> 0.023248168 | W38: =T38^2/1029.4 -> 0.02938605 | X38: =V36-W38 -> 0.030858388
A39: 4200 | B39: =IF(Sketch!#REF!="","",Sketch!#REF!) -> #REF! | D39: =IF(Sketch!D48<>"",Sketch!D48,"") -> Sands | E39: =IF(Sketch!E39<>"",Sketch!E39,"")
A40: 5700 | B40: =IF(Sketch!B46="","",Sketch!B46) | D40: =IF(Sketch!D52<>"",Sketch!D52,"") -> Tubb | E40: =IF(Sketch!E40<>"",Sketch!E40,"") | O40: Logging: tag @ 5098' | S40: Prod casing volume: | T40: =V38*U38 -> 232.48168 | U40: bbl
A41: 5800 | B41: =IF(Sketch!B52="","",Sketch!B52) -> 5362.3 | D41: =IF(Sketch!D53<>"",Sketch!D53,"") -> Sands | E41: =IF(Sketch!E41<>"",Sketch!E41,"") | O41: Schlumberger Triple-Combo | S41: Prod annular vol to shoe: | T41: =X38*(U36-U22) -> 280.81133 | U41: bbl
A42: 5900 | B42: =IF(Sketch!#REF!="","",Sketch!#REF!) -> #REF! | D42: =IF(Sketch!#REF!<>"",Sketch!#REF!,"") -> #REF! | E42: =IF(Sketch!E42<>"",Sketch!E42,"") | S42: Prod annular vol shoe to surf: | T42: =(V22-W38)*U22 -> 30.872613 | U42: bbl
...

Sheet Tech Data
A1: =Sketch!A1&" Technical Data" -> Waddell TR 3 #3813 Technical Data
A3: Mud Properties
A4: Hole Size | C4: Mud Type | F4: Weight (ppg) | H4: Funnel Visc (s/qt) | J4: PV | K4: YP | L4: FL | M4: pH | O4: Pm | P4: MBT | Q4: %LGS
A5: 17-1/2" | C5: FW / Gel / Lime | F5: 8.3 - 8.7 | H5: 33-36 | J5: 2-6 | K5: 2-6 | L5: NC | M5: 9.0-10 | O5: 1 | P5: - | Q5: < 6
A6: 17-1/2" (300' F/TD) | C6: FW / Gel / Lime / Starch | F6: 8.3 - 8.7 | H6: =H5 -> 33-36 | J6: 2-6 | K6: 2-6 | L6: <10 cc | M6: 9.0-10 | O6: 1 | P6: - | Q6: < 6
A7: 11" | C7: Brine / Salt Gel / Lime | F7: 10.0-10.2 | H7: 28-32 | J7: 1-3 | K7: 1-3 | L7: NC | M7: 10 | O7: - | P7: - | Q7: < 2
A8: 11" (300' F/TD) | C8: Brine / Salt Gel / Lime / Starch | F8: =F7 -> 10.0-10.2 | H8: 30-32 | K8: 1-3 | L8: <20 cc | M8: 10 | O8: - | P8: - | Q8: < 2
A9: 6-3/4" | C9: Brine / Salt Gel / Lime | F9: 10.0-10.2 | H9: 28-32 | J9: 1-3 | K9: 1-3 | L9: NC | M9: 10 | O9: - | P9: - | Q9: < 2
A10: 6-3/4" (300' F/TD) | C10: Brine / Salt Gel / Lime / Starch | F10: =F9 -> 10.0-10.2 | H10: 30-32 | K10: 1-3 | L10: <20 cc | M10: 10 | O10: - | P10: - | Q10: < 2
A13: Bit & BHA Information
A14: Hole Size | B14: Bit Type | C14: Vendor | D14: Model | F14: Jets | G14: TFA (in2) | H14: ROP Target | I14: BHA
A15: 17-1/2" | B15: PDC | C15: Halliburton | D15: GT65DM | F15: 3x22s | H15: See Parameter | I15: Bit > Bit sub & float > 2 x 8"DC > XO > 10 x 6-1/2" DC > 10 x 4-1/2" HWDP
A16: 11" | B16: PDC | C16: Halliburton | D16: GT65DMHEO | F16: 6x15s | G16: 1.035 | H16: See Parameter | I16: Bit > Motor w/float > Monel w/ MWD survey tool > XO > 12-1/4" STAB > 1 x 8" DC > 12-1/4" STAB > 2 x 8" DC > 10 x 6-1/2" DCs > 10 x 4-1/2" HWDP > 4-1/2" 16.6# G-105 EU DP
A17: 6-3/4" | B17: PDC | C17: Halliburton | D17: GT65WRK | F17: 6x15s | G17: 1.035 | H17: See Parameter | I17: Bit > Motor w/float > Monel w/ MWD survey tool > XO >6-1/2" STAB > 1 x 4-1/2" DC > 6-1/2" STAB > 31 x 4-1/2" HWDP > 4-1/2" 16.6# G-105 EU DP
A18: **Check with Engr to confirm bit vendor ** All parameters are recommended not hard limits
A20: Motor Specs
A21: Size | B21: Stages | D21: Vendor | E21: Speed Ratio | G21: Flow Range | I21: Speed Range | K21: Max Diff Press | M21: Max Torque | O21: Bit to Bend
A22: 8" | B22: 7/8 | D22: Baker | E22: 0.15 rev / gal | G22: 395 - 900 gpm | I22: 60-135 rpm | K22: 1150 | M22: 13500 | O22: 1.83
A23: 5-1/8" | B23: 5/6 6.5 | D23: Baker | E23: 0.51 rev / gal | G23: 106-360 gpm | I23: 55-185 rpm | K23: 1340 | M23: 5100 | O23: 1.8
A25: Casing Data
A26: Interval | B26: Size (in) | C26: Grade | D26: Weight (ppf) | E26: Thread | F26: ID (in) | G26: Drift (in) | H26: Cap (bbl / ft) | I26: Collapse (psi) | K26: Burst (psi) | M26: Tension (1000 lb) | O26: Make-up (ft-lb)
I27: Rated | J27: 0.8 | K27: Rated | L27: 0.8 | M27: Rated | N27: 0.8 | O27: Min | P27: Opt | Q27: Max
A28: Surface | B28: 13-3/8 | C28: H-40 | D28: 48 | E28: STC | F28: 12.715 | G28: 12.559 | H28: 0.157 | I28: 770 | J28: =ROUNDDOWN(0.8*I28,0) -> 616 | K28: 1730 | L28: =ROUNDDOWN(0.8*K28,0) -> 1384 | M28: 541 | N28: =ROUNDDOWN(0.8*M28,0) -> 432 | S28: =ABS(P28-O28)/P28 -> #DIV/0! | T28: =ABS(P28-Q28)/P28 -> #DIV/0!
A29: Int | B29: 8-5/8 | C29: J-55 | D29: 32 | E29: LTC | F29: 7.921 | G29: 7.796 | H29: 0.0609 | I29: 2530 | J29: =ROUNDDOWN(0.8*I29,0) -> 2024 | K29: 3930 | L29: =ROUNDDOWN(0.8*K29,0) -> 3144 | M29: 417 | N29: =ROUNDDOWN(0.8*M29,0) -> 333
A30: Prod | B30: 5-1/2 | C30: L-80 | D30: 20 | E30: LTC | F30: 4.778 | G30: 4.653 | H30: 0.0222 | I30: 8830 | J30: =ROUNDDOWN(0.8*I30,0) -> 7064 | K30: 9190 | L30: =ROUNDDOWN(0.8*K30,0) -> 7352 | M30: 416 | N30: =ROUNDDOWN(0.8*M30,0) -> 332 | O30: 1850 | P30: 2470 | Q30: 3090 | S30: =(P30-O30)/P30 -> 0.25101215 | T30: =ABS(P30-Q30)/P30 -> 0.25101215
A32: Centralizer Program
A33: Casing String | C33: Interval | F33: Spacing | I33: Est Joint Count | L33: Est Turbolizers | O33: Est Centralizers
A34: 13-3/8" | C34: 1st and 2nd joints | F34: 1 per joint | I34: 2 | L34: 0 | O34: 2
A35: 13-3/8" | C35: Thereafter to surface | F35: 1 every 4th collar | I35: =ROUNDUP((Sketch!J28-85)/42.5,0) -> 20 | L35: 0 | O35: =ROUNDUP(I35/4,0) -> 5
A36: 13-3/8" - Total | I36: =SUM(I34:J35) -> 22 | L36: =SUM(L34:M35) -> 0 | O36: =SUM(O34:Q35) -> 7
A37: 8-5/8" | C37: 1st and 2nd joints | F37: 1 per joint | I37: 2 | L37: 0 | O37: =SUM(I37:N37) -> 2
A38: 8-5/8" | C38: 3rd jnt to top of San Andres | F38: 1 per 2 jts | I38: =ROUND(((Sketch!J46-Sketch!B42)/42.5-2),0) -> 9 | L38: 0 | O38: =ROUND(SUM(I38:N38)/2,0) -> 5
A39: 8-5/8" | C39: San Andres - Surf | F39: 1 per 6 jts | I39: =ROUND(Sketch!B42/42.5,0) -> 83 | L39: 0 | O39: =ROUND(SUM(I39:N39)/6,0) -> 14
A40: 8-5/8" Total | I40: =SUM(I37:K39) -> 94 | L40: =SUM(L37:N39) -> 0 | O40: =SUM(O37:Q39) -> 21 | W40: =(11^2-8.625^2)/1029.4 -> 0.045278196 | X40: bbl/ft
A41: 5-1/2" | C41: 1st and 2nd joints | F41: 1 per joint | I41: 2 | L41: 0 | O41: =I41 -> 2 | W41: =(7.875^2-5.5^2)/1029.4 -> 0.030858388 | X41: bbl/ft | AA41: =W40/W41 -> 1.4672897
A42: 5-1/2" | C42: 3rd jnt to 100' above Int shoe | F42: 1 every 3rd collar | I42: =ROUND(((Sketch!J61-(Sketch!J46-100))/42.5-2),0) -> 142 | L42: 0 | O42: =ROUNDUP(I42/3,0) -> 48
A43: 5-1/2" | C43: therafter to surface | F43: 1 every 6th collar | I43: =ROUNDUP((Sketch!J46-100)/42.5,0) -> 92 | L43: 0 | O43: =ROUNDUP(I43/6,0) -> 16
A44: 5-1/2" - Total | I44: =SUM(I41:J43) -> 236 | L44: =SUM(L41:M43) -> 0 | O44: =SUM(O41:Q43) -> 66
A46: Cement Program
A47: Casing | B47: Slurry | C47: Volume (sx) | D47: Cement | N47: Weight (ppg) | O47: Yield (ft3/sk) | P47: Water (gal/sk) | Q47: Volume (bbls) | R47: Gauge (bbls) | S47: OH Excess | T47: Quoted Price | U47: CMT Tops | Y47: OH Excess calculation (Int-lead)
...

Sheet Interval Specific Parameter
A1: =Sketch!B1&" Interval Specific Parameter Map" -> Waddell TR 3 #3813 Interval Specific Parameter Map
A4: =Sketch!J15&" Surface ("&'Tech Data'!D15&" "&'Tech Data'!E15&")" -> 17-1/2" Surface (GT65DM )
A5: Start | B5: End | C5: ROP Target | D5: WOB Min | E5: WOB Max | F5: WOB Target | G5: Rotary Min | H5: Rotary Max | I5: Rotary Target | J5: GPM Min | K5: GPM Max | L5: GPM Target | M5: Motor Diff | N5: Total RPM | O5: Interval Notes
A6: 0-500' | B6: Surf | C6: Max | D6: 10 | E6: 30 | F6: 20 | G6: 85 | H6: 120 | I6: 110 | J6: 400 | K6: 500 | L6: 500 | M6: NA | N6: =I6 -> 110 | O6: Reach targets as soon as 8" collars clear conductor.
A7: ="500-"&Sketch!J28&"'" -> 500-900' | B7: Red Beds | C7: Max | D7: 25 | E7: 40 | F7: 35 | G7: 105 | H7: 150 | I7: 130 | J7: 400 | K7: 500 | L7: 500 | M7: NA | N7: =I7 -> 130
A9: =Sketch!J29&" Intermediate ("&'Tech Data'!D16&" "&'Tech Data'!E16&")" -> 11" Intermediate (GT65DMHEO )
A10: Depths | B10: Zone | C10: ROP Target | D10: WOB Min | E10: WOB Max | F10: WOB Target | G10: Rotary Min | H10: Rotary Max | I10: Rotary Target | J10: GPM Min | K10: GPM Max | L10: GPM Target | M10: Motor Diff Target | N10: Total RPM (.21rev/gal) | O10: DOC | P10: Interval Notes | T10: DOC | V10: 0.28
A11: =Sketch!J28&"-"&(Sketch!B34)&"'" -> 900-2278.7' | B11: Rustler-Yates | D11: 30 | E11: 45 | F11: 35 | G11: 50 | H11: 70 | I11: 65 | J11: 450 | K11: 550 | L11: 550 | M11: 400+ | N11: =MROUND(I11+L11*0.21,5) -> 180 | O11: =(C11)/(N11*5) -> 0 | P11: Salado Salt formation, ensure to drill out with 10 ppg Brine. | T11: =(C11)/(N11*5) -> 0
A12: =(Sketch!B34-50)&"-"&(Sketch!B34+50)&"'" -> 2228.7-2328.7' | B12: Yates Deviation Zone | C12: 150 | D12: 35 | E12: 45 | F12: 40 | G12: 65 | J12: 450 | K12: 550 | L12: 500 | M12: 400+ | N12: =MROUND(G12+(L12*0.21),5) -> 170 | O12: =(C12)/(N12*5) -> 0.17647059 | P12: Deviations seen in the salts, especially around 2,400'. Focus on WOB and RPM parameters
A13: =(Sketch!B34+50)&"'"&"-"&MROUND(Sketch!B42-50,5)&"'" -> 2328.7'-3465' | B13: Yates-San Andres | D13: 35 | E13: 45 | F13: 40 | G13: 60 | H13: 80 | I13: 65 | J13: 450 | K13: 550 | L13: 500 | M13: 400+ | N13: =MROUND(I13+L13*0.21,5) -> 170 | O13: 0 | T13: =(C13)/(N13*5) -> 0
B14: Transition into Grayburg | C14: 90 | F14: N/A | G14: 55 | J14: 450 | K14: 550 | L14: 450 | M14: N/A | N14: =MROUND(G14+(L14*0.28),5) -> 180 | O14: =(C14)/(N14*5) -> 0.1 | P14: Transition 50' before to 50' past Grayburg. Set ROP Target and Rotary Target through transition with WOB MAX limit set at 40K for stack out safety purpose. | T14: =(C14)/(N14*5) -> 0.1
B15: Grayburg - San Andres Transition | D15: 25 | E15: 35 | F15: 25-28 | G15: 45 | H15: 85 | I15: 70 | J15: 450 | K15: 550 | L15: 490 | M15: 400+ | N15: =MROUND(I15+L15*0.28,5) -> 205 | O15: =(C15)/(N15*5) -> 0 | P15: Water flows possible, can have high H2S concentrations. | T15: =(C15)/(N15*5) -> 0
A16: =MROUND(Sketch!B42-50,5)&"'"&"-"&MROUND(Sketch!B42+50,5)&"'" -> 3465'-3565' | B16: Transition into San Andres | C16: 90 | D16: 30 | E16: 45 | F16: 40 | G16: 55 | J16: 450 | K16: 550 | L16: 500 | M16: 500+ | N16: =MROUND(G16+(L16*0.21),5) -> 160 | O16: =(C16)/(N16*5) -> 0.1125 | P16: Transition 50' before to 50' past San Andres. Focus on WOB and RPM parameters | T16: =(C16)/(N16*5) -> 0.1125
A17: =MROUND(Sketch!B42+50,5)&"'"&"-"&MROUND(Sketch!B46-50,5)&"'" -> #NUM! | B17: San Andres - Glorieta | D17: 30 | E17: 45 | F17: 40 | G17: 50 | H17: 60 | I17: 55 | J17: 450 | K17: 550 | L17: 500 | M17: 500+ | N17: =MROUND(I17+L17*0.21,5) -> 160 | O17: =(C17)/(N17*5) -> 0 | P17: Once San Andres is reached by verification of cuttings, continue to regular drilling. | T17: =(C17)/(N17*5) -> 0
A18: =MROUND(Sketch!B46-50,5)&"-"&MROUND(Sketch!B46+50,5)&"'" -> #NUM! | B18: Transition into Glorieta | C18: 90 | D18: 30 | E18: 45 | F18: 40 | G18: 55 | J18: 450 | K18: 550 | L18: 500 | M18: 500+ | N18: =MROUND(G18+(L18*0.21),5) -> 160 | O18: =(C18)/(N18*5) -> 0.1125 | P18: Transition 50' before to 50' past Glorieta. Focus on WOB and RPM parameters | T18: =(C18)/(N18*5) -> 0.1125
A19: =MROUND(Sketch!B46+50,5)&"-"&MROUND(Sketch!B49-50,5)&"'" -> 50-4995' | B19: Glorieta - Upper Clearfork | D19: 30 | E19: 45 | F19: 40 | G19: 50 | H19: 60 | I19: 55 | J19: 450 | K19: 550 | L19: 500 | M19: 400+ | N19: =MROUND(I19+L19*0.21,5) -> 160 | O19: =(C19)/(N19*5) -> 0 | T19: =(C19)/(N19*5) -> 0
A21: =Sketch!J47&" Production ("&'Tech Data'!D17&" "&'Tech Data'!E17&")" -> 6-3/4" Production (GT65WRK )
A22: =MROUND(Sketch!B49-50,5)&"-"&MROUND(Sketch!B49+50,5)&"'" -> 4995-5095' | B22: Transition into Upper Clearfork | C22: 90 | D22: 30 | E22: 40 | F22: 35 | G22: 55 | J22: 450 | K22: 550 | L22: 500 | M22: 500+ | N22: =MROUND(I22+L22*0.21,5) -> 105 | P22: Transition 50' before to 50' past Upper Clearfork. Focus on WOB and RPM parameters | T22: =(C22)/(N22*5) -> 0.17142857
A23: =MROUND(Sketch!B49+50,5)&"-"&MROUND(Sketch!B52-50,5)&"'" -> 5095-5310' | B23: Upper Clearfork - Tubb | D23: 30 | E23: 40 | F23: 35 | G23: 60 | H23: 70 | I23: 65 | J23: 450 | K23: 550 | L23: 500 | M23: 500+ | N23: =MROUND(I23+L23*0.21,5) -> 170 | T23: =(C23)/(N23*5) -> 0
A24: =MROUND(Sketch!B52-50,5)&"-"&MROUND(Sketch!B52+50,5)&"'" -> 5310-5410' | B24: Transition into Tubb | C24: 85 | D24: 30 | E24: 40 | F24: 35 | G24: 55 | J24: 450 | K24: 550 | L24: 500 | M24: 500+ | N24: =MROUND(G24+(L24*0.21),5) -> 160 | O24: =(C24)/(N24*5) -> 0.10625 | P24: Transition 50' before to 50' past Tubb. Focus on WOB and RPM parameters
A25: =MROUND(Sketch!B52+50,5)&"-"&MROUND('Geo-Prog'!C34,5)&"'" -> 5410-5420' | B25: Tubb - Lower Clearfork | D25: 30 | E25: 40 | F25: 35 | G25: 60 | H25: 70 | I25: 65 | J25: 450 | K25: 550 | L25: 500 | M25: 400+ | N25: =MROUND(I25+L25*0.21,5) -> 170 | O25: =(C25)/(N25*5) -> 0 | P25: High WOB and Low RPMS will keep bit engaged in ratty formation
A26: =MROUND('Geo-Prog'!C34+50,5)&"-"&MROUND(Sketch!B57-50,5)&"'" -> 5470-7005' | B26: Lower Clearfork - Wichita Albany | D26: 30 | E26: 40 | F26: 35 | G26: 60 | H26: 70 | I26: 65 | J26: 450 | K26: 550 | L26: 500 | M26: 500+ | N26: =MROUND(I26+L26*0.21,5) -> 170 | P26: Severe losses are possible
A27: =MROUND(Sketch!B57-50,5)&"-"&MROUND(Sketch!B57+50,5)&"'" -> 7005-7105' | B27: Transition into Wolfcamp | C27: 85 | D27: 30 | E27: 40 | F27: 35 | G27: 55 | J27: 450 | K27: 550 | L27: 500 | M27: 500+ | N27: =MROUND(G27+(L27*0.21),5) -> 160 | P27: Transition 50' before to 50' past Wolfcamp. Focus on WOB and RPM parameters
A28: =MROUND(Sketch!B57+50,5)&"-"&MROUND(Sketch!B61,5)&"'" -> 7105-10000' | B28: Wolfcamp - TD | D28: 30 | E28: 40 | F28: 35 | G28: 50 | H28: 60 | I28: 55 | J28: 450 | K28: 550 | L28: 500 | M28: 500+ | N28: =MROUND(I28+L28*0.21,5) -> 160
A29: During all Transitions highlighted in red, enable the ROP set point to ROP Target. Remove the WOB set points through the transition zones so it doesn't limit ROP.
A30: On all formations, except the transitions, remove ROP set point on auto driller (or set to 400 so it doesn’t limit WOB). In these non-control drill intervals use WOB set points.
P47: 6.35 | Q47: =C47*O47*0.1781 -> 0

Sheet Contacts
A1: =Sketch!B1&" Contact List" -> Waddell TR 3 #3813 Contact List
A2: =Sketch!S1 -> Savanna #417
A4: Well Site Contacts
A5: Personnel | C5: Contact | D5: Phone
A6: Toolpusher
A7: Toolpusher
A8: Rig Supervisor (Day) | C8: Clint Valentine | D8: 337-380-8846
A9: Rig Supervisor (Day) | C9: Bryan Stringer | D9: 337-257-3279
A10: Rig Supervisor (Night)
A11: Rig Supervisor (Night)
A13: Vendor Contacts
A14: Services | B14: Company/Person | C14: Location | D14: Phone | E14: Line
A15: Hospital/Emergency | B15: Ward Memorial Hospital | C15: 406 S. Gary Ave Monahans, X 79756 | D15: 911 432-943-6703 | E15: Emergency Office
A16: Sheriff | B16: Ward County Sherriff's Office | C16: 300 East 4th Monahans, TX 79756 | D16: 432-943-6703 | E16: Office
A17: Sheriff | B17: Crane County Sheriff's Office | C17: 201 W 6th St, Crane, TX 79731 | D17: 432-558-3571 | E17: Office
A18: Mud Loggers | B18: Geo-site | C18: Midland, TX | D18: 325-655-4356 | E18: Mobile
A19: EDR (Electronic Drilling Recorder) | B19: Pason | C19: Midland, TX | D19: 806-281-8370 | E19: Mobile
A20: All Casing | B20: Patriot Threading | C20: Midland, TX | D20: 281-222-3936 903-235-3985 | E20: Mobile
A21: 5-1/2" Production Casing (minimum 2 day notice) | B21: Tubular Synergy Group | C21: Midland, TX | D21: 432-559-4742 | E21: Cell
A22: Bits | B22: Cap Rock | C22: Midland, TX | D22: 432-230-0440 | E22: mobile
A23: Bits (Production Hole) | B23: Halliburton - Jeff Hardin | C23: Midland, TX | D23: 903-780-5127 | E23: mobile
A24: Bits | B24: Hughes | C24: Odessa, TX | D24: 432-230-6973 | E24: mobile
A25: Bits | B25: NOV | C25: Odessa, TX | D25: 432-288-5150 | E25: cell
... A34: Fresh Water (Well) | B34: Kenny Bradford | C34: Midland, TX | D34: 432-813-7985 | E34: Mobile
A35: Casing Crews / LD | B35: Bid out:
A36: Casing Inspection Services | B36: Bid out:
A37: Cementing Services | B37: Basic Energy Services | C37: Midland, TX | D37: 432-687-1994 | E37: Dispatch
A38: Cementing Services | B38: Pro-Petro | C38: Midland, TX | D38: 432-425-4881 | E38: Mobile
A39: Centralizers | B39: Innovex | C39: Midland, TX | D39: 432-250-9652 | E39: Office
A40: Welder | B40: Double A Welding | C40: Monahans, Tx | D40: 432-208-5244 | E40: Mobile
A41: DC Inspection | B41: Bid Out
A42: Diesel | B42: Blue Streak | C42: Midland, TX | D42: 432-262-1515 | E42: mobile
A43: Diesel | B43: Pilot Thomas | C43: Midland, TX | D43: 432-813-6643 | E43: Mobile
A44: Diesel | B44: Pilot | C44: Midland, TX | D44: 432-813-6643 | E44: mobile
A45: Directional (MWD, Motor, IBS) | B45: Wellbenders | C45: Midland, TX | D45: 210-643-2960 832-493-1844 | E45: cell(s)
A46: Dirt Contractor/ Pit lining | B46: Ian Barry | C46: Midland, TX | D46: 713-248-4672 | E46: Mobile | O46: Survey at <500' intervals after the Salado
A47: Downhole Rentals | B47: Alliance | C47: Midland, TX | D47: 307-789-0212 | E47: office
A48: Downhole Rentals | B48: Triumph | C48: Odessa, TX | D48: 432-704-5130 | E48: office
A49: Downhole Rentals | B49: Spidle Turbeco | C49: Odessa, TX | D49: 432-561-9495 | E49: office
A50: DP Corrosion | B50: Savanna/Corrosion LTD | E50: Office Mobile
...

Sheet Prog
A1: General Drilling Procedure
A2: =Sketch!A1&" Drilling Procedure" -> Waddell TR 3 #3813 Drilling Procedure
C3: This program contains the guiding procedures to be followed in the development of this property. It is meant only as a guide under normal-predicted conditions during the drilling operation of this well. As actual conditions differ from predicted, the Drilling Foreman on location, representing Blackbeard Operating, LLC will take appropriate actions needed to continue the drilling operation in the safest and most economical method possible. All changes will be reported to the drilling/operations engineer as soon as drilling operations allow. Please read COVID-19 protocol below. The comments, procedures, methods and equipment designs within this document are proprietary to Blackbeard Operating, LLC. Any use of said materials and procedures without authorization from Blackbeard Operating, LLC is prohibited.
A4: Surface Hole
A5: Prep Location
A6: 1 | C6: Preview location prior to rig mobilization to confirm that dimensions meet operational needs, the conductor is set, and the rat hole and mouse hole are drilled.
A7: 2 | C7: Read all permits and regulatory paperwork carefully to ensure all regulatory requirements are satisfied.
A8: 3 | C8: Notify RRC 24 hours prior to spudding, running casing, and cementing. Note the date, time, person contacted, and job # on the daily report.
A9: 4 | C9: Tubular requirement notifications should be made to pipe vendor in a timely fashion (minimum 2 days notice). Clean, drift, visually inspect, and tally all casing on location.
A10: Drill & Survey Surface Hole
A11: 5 | B11: a. | C11: PU 17-1/2" surface bit and BHA per the Technical Data sheet (unless otherwise instructed by the Midland Office). Drill out with fresh water. Must run floats in BHA per TRRC. Take inclination survey within 500' from surface (all surveys thereafter 500'-1000'). If inclination exceeds 2.5°, back off weight and bring back towards vertical. (Increase the number of surveys to 1 per 300' if inclination exceeds 2.5° resume 1 per 500' when inclination is under 2.0°.)
B12: c. | C12: Maintain mud properties per Technical Data Sheet. Circulate inner reserve pit and allow native mud to build funnel vis to ~32-34s. Only go into steel pits if necessary to control losses.
B13: d | C13: Mix 2 sx paper per 100' drilled. From slug pit, pump ~10 bbls of high visc sweep every 100'-200' drilled. Circulate and pump paper sweeps, as necessary, before connections to ensure hole is clean and avoid packoffs.
A14: 6 | B14: a. | C14: Drill to match casing strap. Do not set casing more than 200’ below the protected depth specified in the TCEQ Water Board Letter unless an approved Application for Alternate Surface Casing Program is attached.
B15: b. | C15: Circulate through steel pits and add 20 sx starch to <10cc water loss 300' before TD.
A16: 7 | B16: a. | C16: At TD circulate hole clean.
B17: b. | C17: TOH at an even and steady pace. The Redbeds in this field can swell and become very tight. If this happens, pull very slow and steady till pipe becomes free again. Use surface jars if necessary. Do not pull more than DC weight.
A18: Run Surface Casing
A19: 8 | C19: Run 1 joint between the Texas pattern guide shoe and the float collar. Thread lock all connections from the guide shoe to the top of the float collar. Use Bestolife 2000 thread compound (or equivalent) on the remaining connections. Be certain not to use any thread compound containing lead or zinc.
A20: 9 | C20: Install centralizers as specified on Technical Data Sheet.
A21: 10 | C21: Ensure a casing swage is on the floor to wash down casing as necessary. Keep casing as full as possible to help maintain weight. If you cannot wash casing down, call Superintendent to discuss forward plan. If casing becomes stuck, be prepared to run 1” pipe down annulus to wash away bridge.
A22: 11 | C22: Tag bottom and pick up two feet, circulate one to two casing volumes at max loss-free rate.
A23: Cement Surface Casing
A24: 12 | C24: Ensure cementing company has analyzed water samples for cementing.
A25: 13 | C25: Pump 20 bbl FW ahead of cement. Pump cement slurry as defined in the Technical Data sheet. Catch wet and dry samples throughout job, sending dry samples to Midland if a problem arises. Plan to circulate cement to surface.
A26: 14 | C26: Displace with FW. Bump the plug with 500 psi over final displacement pressure and hold for +/- 5 minutes. DO NOT OVERDISPLACE. Bleed off pressure and check float equipment. Send a copy or ensure that cementer sends a copy of pressure chart from job to Midland Office for well file.
A27: 15 | C27: If cement does not circulate to surface, notify the RRC; prepare for a temp survey and 1" top out job.
A28: NU WH & BOP
A29: 16 | C29: Install 13-3/8" SOW x 13-5/8" 3M casing head, weld inside & outside, test void to 500 psi for a minimum of 5 min.
A30: 17 | C30: Install BOP stack consisting of a drilling spool with choke and kill lines, double rams with pipe rams on top and blind rams on bottom, and an annular preventer with room for a rotating head on top. Should room not be available for the drilling spool, tie choke and kill lines to side outlets below blind rams.
A31: 18 | C31: Test blind rams, manifold, and valves to Low 250psi & High 1,500psi prior to drilling out. Test manifold first & use a test plug if WOC time has not been reached (6hrs for Tail 500psi UCS). Keep a copy of test chart in well file for reference throughout the well. Inspect accumulator unit to ensure that precharge pressures and oil levels are within API specifications. Record tests and inspections on the IADC tour report. Line up for hard shut-in (Choke and first valve downstream of choke in closed position).
A32: 19 | C32: WOC for a total of 6 hrs before testing casing (500 psi for tail UCS). Prior to drilling out, pressure test the casing to 1000 psig / 30 min per TRRC. If more than 10% pressure is lost during test, call Midland Office for plan forward. Keep a copy of test chart in well file for reference throughout the well. Do not drill out until after 9:05hrs passed since plug bumped (100 psi for lead UCS).
A33: Intermediate Hole
A34: Drill Intermediate Hole
A35: 1 | C35: R/U a rotating head and H2S risk mitigation package.
A36: 2 | B36: a. | C36: No FIT test required IF all of the following requirements are met: 1) CMT to surface 2) Wet samples set up 3) Hard CMT in shoe 4) Compressive strength wait time is met. Contact office to discuss as needed.
B37: b. | C37: Test annular and pipe rams to 250psi low and high 1500psi (positive test). Record tests and inspections on the IADC tour report and BBO drilling report. Drill out with brine water.
B38: c. | C38: Drill out with a 12-1/4" bit and BHA per the Technical Data sheet (unless otherwise instructed by the Midland Office). Drill out with brine water (take sample of brine water from trucks and have mud engineer test chloride level and list on report). Must run floats in BHA per TRRC. Run inclination only survey tool in BHA & take survey 200' out from casing.
B39: d. | C39: When drilling with a motor, differential pressure should be (200-500 psi).
B40: e. | C40: Operate pipe rams daily and blind rams on trips.
...

Sheet Geo-Prog
B5: Geologic Prognosis - Vertical Well | I5: =Sketch!P4 -> CX3818
B7: WELL NAME: | C7: =Sketch!B1 -> Waddell TR 3 #3813 | F7: FIELD OR PROSPECT: | I7: =Sketch!P10 -> University Waddell (Devonian) | R7: Comments:
B8: SURFACE LOCATION: | C8: =Sketch!E4&", "&Sketch!E6&", "&Sketch!E10&", TX" -> 2010' FSL, 650' FWL, Sec 22, Blk B-25, Crane, TX
B9: API Number: | C9: =Sketch!P7 -> 42-103-36784 | E9: RRC Permit Number: | I9: =Sketch!P6 -> 868552 | K9: Drilling Rig: | L9: =Sketch!S1 -> Savanna #417
B10: Driving Directions: | C10: SEE ATTACHED MAP FOR DIRECTIONS
B11: LAT/LON (NAD83): | C11: =Sketch!E8 -> 31.546657, -102.490691 | G11: KB: | K11: =D24 -> 2777
B12: LAT/LON (NAD27): | C12: =Sketch!E9 -> 31.546521, -102.490269 | G12: GROUND ELEVATION: | K12: =Sketch!S8 -> 2765
B13: PRIMARY OBJECTIVES: | D13: Wolfcamp | G13: PROPOSED TOTAL DEPTH: | K13: =Sketch!J61 -> 10000
B14: SECONDARY OBJECTIVES: | D14: Glorieta/Clearfork
B15: KNOWN DRILLING HAZARDS: | D15: Rustler Anhydrite, possible lost circulation. Yates, possible water flow. See depths below.
B16: OPEN-HOLE LOGGING PROGRAM: | D16: None
B17: RECOMMENDED CORING AND TESTING PROGRAM: | F17: None
B18: WELLSITE SUPERVISION: | D18: Bryan Stringer Cell: 337-257-3279 -or- Clint Valentine Cell: 337-380-8846
B19: MUD LOGGER: | D19: Geo-site Cell: 325-655-4356 *Start 2 man mud logging after drilling out of surface casing
B20: GEOLOGIST: | D20: Rene Wiksveen 432-230-7629, rwiksveen@blackbeardoperating.com
B21: ESTIMATED GEOLOGIC TOPS
C22: SUBJECT WELL | F22: PRIMARY CORRELATION WELLS (NAME, LOC.):
C23: EST. KB: | D23: 12 | F23: Waddell WN #272 (1,300' E) | I23: Waddell WN #708 (1,870' SE)
C24: ELEV_KB: | D24: =K12+D23 -> 2777 | F24: ELEV_KB: | G24: 2695 | I24: ELEV_KB: | J24: 2689
B25: FORMATION | C25: DEPTH | D25: SS | F25: DEPTH | G25: SS | I25: DEPTH | J25: SS | L25: COMMENTS
B26: GAU | C26: 450 | D26: =D$24-C26 -> 2327 | F26: =C26 -> 450 | G26: =G$24-F26 -> 2245 | I26: =C26 -> 450 | J26: =$J$24-I26 -> 2239 | L26: Water board Letter
B27: SWR 13 Excptn Letter | C27: 900 | D27: =D$24-C27 -> 1877 | F27: =C27 -> 900 | G27: =G$24-F27 -> 1795 | I27: =C27 -> 900 | J27: =$J$24-I27 -> 1789 | L27: Possible lost circulation
B28: Yates | C28: =D$24-D28 -> 2278.7 | D28: 498.3 | F28: 2155 | G28: =G$24-F28 -> 540 | I28: 2150 | J28: =$J$24-I28 -> 539
B29: Queen | C29: =D$24-D29 -> 3056.3 | D29: -279.3 | F29: 2907 | G29: =G$24-F29 -> -212 | I29: 2901 | J29: =$J$24-I29 -> -212
B30: San Andres | C30: =D$24-D30 -> 3515.8 | D30: -738.8 | F30: 3412 | G30: =G$24-F30 -> -717 | I30: 3407 | J30: =$J$24-I30 -> -718 | L30: Possible water flow
B31: ** Glorieta | C31: =D$24-D31 -> 4550.2 | D31: -1773.2 | F31: 4458 | G31: =G$24-F31 -> -1763 | I31: 4414 | J31: =$J$24-I31 -> -1725 | L31: Dolomite
B32: ** Upper Clearfork | C32: =D$24-D32 -> 5042.7 | D32: -2265.7 | F32: 4860 | G32: =G$24-F32 -> -2165 | I32: 4807 | J32: =$J$24-I32 -> -2118 | L32: Dolomite
B33: Tubb | C33: =D$24-D33 -> 5362.3 | D33: -2585.3 | F33: 5178 | G33: =G$24-F33 -> -2483 | I33: 5138 | J33: =$J$24-I33 -> -2449 | L33: Dolomite
B34: ** Lower Clearfork | C34: =D$24-D34 -> 5422.3 | D34: -2645.3 | F34: 5237 | G34: =G$24-F34 -> -2542 | I34: 5181 | J34: =$J$24-I34 -> -2492 | L34: Dolomite
B35: Wichita-Albany | C35: =D$24-D35 -> 6047.3 | D35: -3270.3 | F35: 5868 | G35: =G$24-F35 -> -3173 | I35: 5855 | J35: =$J$24-I35 -> -3166 | L35: Limestone/Dolomite
B36: * Wolfcamp | C36: =D$24-D36 -> 7053 | D36: -4276 | F36: 6861 | G36: =G$24-F36 -> -4166 | I36: 6826 | J36: =$J$24-I36 -> -4137 | L36: Limestone/Dolomite
B37: Wolfcamp Base | C37: =D$24-D37 -> 7317 | D37: -4540 | F37: 7127 | G37: =G$24-F37 -> -4432 | I37: 7109 | J37: =$J$24-I37 -> -4420 | L37: Limestone/Dolomite
B38: Perm Detrital | C38: =D$24-D38 -> 7634.4 | D38: -4857.4 | F38: 7434 | G38: =G$24-F38 -> -4739 | I38: 7399 | J38: =$J$24-I38 -> -4710 | L38: Limestone/Shale
B39: Cisco | C39: =D$24-D39 -> 7840.1 | D39: -5063.1 | F39: 7575 | G39: =G$24-F39 -> -4880 | I39: 7543 | J39: =$J$24-I39 -> -4854 | L39: Limestone
B40: Canyon | C40: =D$24-D40 -> 7903.4 | D40: -5126.4 | F40: 7626 | G40: =G$24-F40 -> -4931 | I40: 7609 | J40: =$J$24-I40 -> -4920 | L40: Limestone
B41: Strawn | C41: =D$24-D41 -> 8038.9 | D41: -5261.9 | F41: 7717 | G41: =G$24-F41 -> -5022 | I41: 7755 | J41: =$J$24-I41 -> -5066 | L41: Limestone/Shale
... B46: Devonian | C46: =D$24-D46 -> 9119 | D46: -6342 | F46: 8764 | G46: =G$24-F46 -> -6069 | I46: 8714 | J46: =$J$24-I46 -> -6025 | L46: Limestone
B47: Total Depth | C47: =Sketch!B61 -> 10000 | D47: =D$24-C47 -> -7223 | F47: 9500 | G47: =G$24-F47 -> -6805 | I47: 9280 | J47: =$J$24-I47 -> -6591
B48: * Primary Objective
B49: ** Secondary Objective
...

Sheet Target Well Data
A1: Vertical - Fullerton | O1: Weight Factor
A2: Recent Wells | G2: Other | K2: Well | L2: Spud | M2: Est Surf ROP | N2: 160 | O2: 0.78 | P2: 1700 | Q2: Suface TD
A3: FCU #8020 | B3: 42495 | M3: Est Prod ROP | N3: 98.5 | O3: 0.77 | P3: 7350 | Q3: Production TD
A4: =A3&" (Record, "&MONTH(B3)&"/"&YEAR(B3)-2000&")" -> FCU #8020 (Record, 5/16) | C4: =C3&" ("&MONTH(D3)&"/"&YEAR(D3)-2000&")" -> (1/-100) | E4: =E3&" ("&MONTH(F3)&"/"&YEAR(F3)-2000&")" -> (1/-100) | G4: =G3&" ("&MONTH(H3)&"/"&YEAR(H3)-2000&")" -> (1/-100) | I4: =I3&" ("&MONTH(J3)&"/"&YEAR(J3)-2000&")" -> (1/-100) | K4: =IF(K3="","Current",K3&" (Current, "&MONTH(L3)&"/"&YEAR(L3)-2000&")") -> Current | M4: =CONCATENATE("Target ",ROUND(N15,1), " days") -> Target 6.1 days
A5: Days | B5: Depth | C5: Days | D5: Depth | E5: Days | F5: Depth | G5: Days | H5: Depth | I5: Days | J5: Depth | K5: Days | L5: Depth | M5: Days | N5: Cum Days | O5: Depth | P5: Description
A6: 0 | B6: 53 | M6: =N6 -> 0 | N6: 0 | O6: 53 | P6: spud
A7: 0.041666667 | B7: 53 | M7: =N7-N6 -> 0.25 | N7: 0.25 | O7: =MIN($P$2,ROUND(N7*N2*$O$2*24+O6,-1)) -> 800 | P7: drill
A8: 0.41666667 | B8: 1669 | M8: =N8-N7 -> 0.30048077 | N8: =(O8-O7)/(N2*O2)/24+N7 -> 0.55048077 | O8: =P2 -> 1700 | P8: TD surf | Q8: =N8 -> 0.55048077
A9: 0.4375 | B9: 1705 | M9: 1.15 | N9: =N8+M9 -> 1.7004808 | O9: =O8 -> 1700 | P9: TD surf to drill Prod
A10: 0.45833333 | B10: 1705 | M10: =N10-N9 -> 1 | N10: =N9+1 -> 2.7004808 | O10: =ROUND(O9+$N$3*$O$3*24*M10,-1) -> 3520 | P10: drill
A11: 0.52083333 | B11: 1705 | M11: =N11-N10 -> 1 | N11: =IF(ROUND(O10+$N$3*O3*24,0)<$P$3,N10+1,(($P$3-$O10)/$N$3/(24*O3)+$N10)) -> 3.7004808 | O11: =ROUND(O10+$N$3*$O$3*24*M11,-1) -> 5340 | P11: drill
A12: 0.54166667 | B12: 1705 | M12: =N12-N11 -> 1 | N12: =IF(ROUND(O11+$N$3*O3*24,0)<$P$3,N11+1,(($P$3-$O11)/$N$3/(24*O3)+$N11)) -> 4.7004808 | O12: =ROUND(O11+$N$3*$O$3*24*M12,-1) -> 7160 | P12: drill
A13: 0.8125 | B13: 1705 | M13: =N13-N12 -> 0.10437955 | N13: =(O13-O12)/(N3*O3*24)+N12 -> 4.8048603 | O13: =P3 -> 7350 | P13: TD prod | Q13: =N13-N9 -> 3.1043795
A14: 0.84375 | B14: 1705 | M14: 0.7 | N14: =N13+M14 -> 5.5048603 | O14: 7350 | P14: TOH log
A15: 0.92708333 | B15: 1705 | M15: 0.6 | N15: =N14+M15 -> 6.1048603 | O15: 7350 | P15: Csg / Cmt | Q15: =SUM(M14:M15) -> 1.3
A16: 1.0625 | B16: 1705
A17: 1.1666667 | B17: 1705
A18: 1.2083333 | B18: 1705
A19: 1.2291667 | B19: 1705
A20: 1.3125 | B20: 1705
A21: 1.34375 | B21: 1705
A22: 1.3854167 | B22: 1705
A23: 1.3958333 | B23: 1705
A24: 1.4166667 | B24: 1705
A25: 1.4479167 | B25: 1705
A26: 1.4895833 | B26: 1705
A27: 1.84375 | B27: 2903
... A501: 5.15625 | B501: 7403

Sheet Wellhead
